[2023-08-02T18:23:21.384+0000] {taskinstance.py:1103} INFO - Dependencies all met for dep_context=non-requeueable deps ti=<TaskInstance: abc_data2bot_etl_dag.export_best_data manual__2023-08-02T18:18:56.434251+00:00 [queued]>
[2023-08-02T18:23:21.390+0000] {taskinstance.py:1103} INFO - Dependencies all met for dep_context=requeueable deps ti=<TaskInstance: abc_data2bot_etl_dag.export_best_data manual__2023-08-02T18:18:56.434251+00:00 [queued]>
[2023-08-02T18:23:21.390+0000] {taskinstance.py:1308} INFO - Starting attempt 2 of 3
[2023-08-02T18:23:21.403+0000] {taskinstance.py:1327} INFO - Executing <Task(PythonOperator): export_best_data> on 2023-08-02 18:18:56.434251+00:00
[2023-08-02T18:23:21.408+0000] {standard_task_runner.py:57} INFO - Started process 28604 to run task
[2023-08-02T18:23:21.411+0000] {standard_task_runner.py:84} INFO - Running: ['***', 'tasks', 'run', 'abc_data2bot_etl_dag', 'export_best_data', 'manual__2023-08-02T18:18:56.434251+00:00', '--job-id', '35', '--raw', '--subdir', 'DAGS_FOLDER/etl_abc_dag.py', '--cfg-path', '/tmp/tmpv7_m2v1z']
[2023-08-02T18:23:21.412+0000] {standard_task_runner.py:85} INFO - Job 35: Subtask export_best_data
[2023-08-02T18:23:21.449+0000] {task_command.py:410} INFO - Running <TaskInstance: abc_data2bot_etl_dag.export_best_data manual__2023-08-02T18:18:56.434251+00:00 [running]> on host 22477bb0878f
[2023-08-02T18:23:21.515+0000] {taskinstance.py:1547} INFO - Exporting env vars: AIRFLOW_CTX_DAG_OWNER='idowu' AIRFLOW_CTX_DAG_ID='abc_data2bot_etl_dag' AIRFLOW_CTX_TASK_ID='export_best_data' AIRFLOW_CTX_EXECUTION_DATE='2023-08-02T18:18:56.434251+00:00' AIRFLOW_CTX_TRY_NUMBER='2' AIRFLOW_CTX_DAG_RUN_ID='manual__2023-08-02T18:18:56.434251+00:00'
[2023-08-02T18:23:27.636+0000] {taskinstance.py:1824} ERROR - Task failed with exception
Traceback (most recent call last):
  File "/home/airflow/.local/lib/python3.7/site-packages/airflow/operators/python.py", line 181, in execute
    return_value = self.execute_callable()
  File "/home/airflow/.local/lib/python3.7/site-packages/airflow/operators/python.py", line 198, in execute_callable
    return self.python_callable(*self.op_args, **self.op_kwargs)
  File "/opt/airflow/dags/export_data.py", line 13, in export_best_performing_data
    best_perfoming_data.to_csv(f, index=False)
  File "/home/airflow/.local/lib/python3.7/site-packages/fsspec/spec.py", line 1569, in close
    self.flush(force=True)
  File "/home/airflow/.local/lib/python3.7/site-packages/fsspec/spec.py", line 1440, in flush
    if self._upload_chunk(final=force) is not False:
  File "/home/airflow/.local/lib/python3.7/site-packages/s3fs/core.py", line 1977, in _upload_chunk
    self.commit()
  File "/home/airflow/.local/lib/python3.7/site-packages/s3fs/core.py", line 1997, in commit
    **self.kwargs,
  File "/home/airflow/.local/lib/python3.7/site-packages/s3fs/core.py", line 1844, in _call_s3
    return self.fs.call_s3(method, self.s3_additional_kwargs, *kwarglist, **kwargs)
  File "/home/airflow/.local/lib/python3.7/site-packages/fsspec/asyn.py", line 88, in wrapper
    return sync(self.loop, func, *args, **kwargs)
  File "/home/airflow/.local/lib/python3.7/site-packages/fsspec/asyn.py", line 69, in sync
    raise result[0]
  File "/home/airflow/.local/lib/python3.7/site-packages/fsspec/asyn.py", line 25, in _runner
    result[0] = await coro
  File "/home/airflow/.local/lib/python3.7/site-packages/s3fs/core.py", line 237, in _call_s3
    await self.set_session()
  File "/home/airflow/.local/lib/python3.7/site-packages/s3fs/core.py", line 378, in set_session
    self.session = aiobotocore.AioSession(**self.kwargs)
AttributeError: module 'aiobotocore' has no attribute 'AioSession'
[2023-08-02T18:23:27.643+0000] {taskinstance.py:1350} INFO - Marking task as UP_FOR_RETRY. dag_id=abc_data2bot_etl_dag, task_id=export_best_data, execution_date=20230802T181856, start_date=20230802T182321, end_date=20230802T182327
[2023-08-02T18:23:27.654+0000] {standard_task_runner.py:109} ERROR - Failed to execute job 35 for task export_best_data (module 'aiobotocore' has no attribute 'AioSession'; 28604)
[2023-08-02T18:23:27.686+0000] {local_task_job_runner.py:225} INFO - Task exited with return code 1
[2023-08-02T18:23:27.711+0000] {taskinstance.py:2653} INFO - 0 downstream tasks scheduled from follow-on schedule check
