[2023-08-02T17:52:19.995+0000] {taskinstance.py:1103} INFO - Dependencies all met for dep_context=non-requeueable deps ti=<TaskInstance: abc_data2bot_etl_dag.load_data_task manual__2023-08-02T17:47:51.050652+00:00 [queued]>
[2023-08-02T17:52:20.009+0000] {taskinstance.py:1103} INFO - Dependencies all met for dep_context=requeueable deps ti=<TaskInstance: abc_data2bot_etl_dag.load_data_task manual__2023-08-02T17:47:51.050652+00:00 [queued]>
[2023-08-02T17:52:20.010+0000] {taskinstance.py:1308} INFO - Starting attempt 3 of 3
[2023-08-02T17:52:20.041+0000] {taskinstance.py:1327} INFO - Executing <Task(PythonOperator): load_data_task> on 2023-08-02 17:47:51.050652+00:00
[2023-08-02T17:52:20.051+0000] {standard_task_runner.py:57} INFO - Started process 11085 to run task
[2023-08-02T17:52:20.059+0000] {standard_task_runner.py:84} INFO - Running: ['***', 'tasks', 'run', 'abc_data2bot_etl_dag', 'load_data_task', 'manual__2023-08-02T17:47:51.050652+00:00', '--job-id', '14', '--raw', '--subdir', 'DAGS_FOLDER/etl_abc_dag.py', '--cfg-path', '/tmp/tmpj7x41mua']
[2023-08-02T17:52:20.061+0000] {standard_task_runner.py:85} INFO - Job 14: Subtask load_data_task
[2023-08-02T17:52:20.117+0000] {task_command.py:410} INFO - Running <TaskInstance: abc_data2bot_etl_dag.load_data_task manual__2023-08-02T17:47:51.050652+00:00 [running]> on host 22477bb0878f
[2023-08-02T17:52:20.187+0000] {taskinstance.py:1547} INFO - Exporting env vars: AIRFLOW_CTX_DAG_OWNER='idowu' AIRFLOW_CTX_DAG_ID='abc_data2bot_etl_dag' AIRFLOW_CTX_TASK_ID='load_data_task' AIRFLOW_CTX_EXECUTION_DATE='2023-08-02T17:47:51.050652+00:00' AIRFLOW_CTX_TRY_NUMBER='3' AIRFLOW_CTX_DAG_RUN_ID='manual__2023-08-02T17:47:51.050652+00:00'
[2023-08-02T17:52:33.043+0000] {taskinstance.py:1824} ERROR - Task failed with exception
Traceback (most recent call last):
  File "/home/airflow/.local/lib/python3.7/site-packages/sqlalchemy/engine/base.py", line 1911, in _execute_context
    cursor, statement, parameters, context
  File "/home/airflow/.local/lib/python3.7/site-packages/sqlalchemy/engine/default.py", line 736, in do_execute
    cursor.execute(statement, parameters)
psycopg2.errors.DependentObjectsStillExist: cannot drop table idowilek6169_staging.orders because other objects depend on it
DETAIL:  view idowilek6169_staging.stg_orders depends on table idowilek6169_staging.orders
view idowilek6169_analytics.stg_orders depends on table idowilek6169_staging.orders
HINT:  Use DROP ... CASCADE to drop the dependent objects too.


The above exception was the direct cause of the following exception:

Traceback (most recent call last):
  File "/home/airflow/.local/lib/python3.7/site-packages/airflow/operators/python.py", line 181, in execute
    return_value = self.execute_callable()
  File "/home/airflow/.local/lib/python3.7/site-packages/airflow/operators/python.py", line 198, in execute_callable
    return self.python_callable(*self.op_args, **self.op_kwargs)
  File "/opt/airflow/dags/load_data.py", line 26, in load_data_warehouse
    data_df.to_sql(name=data_table_name, con=postgres_engine, if_exists = 'replace', schema= staging_schema_name,index = False)
  File "/home/airflow/.local/lib/python3.7/site-packages/pandas/core/generic.py", line 2882, in to_sql
    method=method,
  File "/home/airflow/.local/lib/python3.7/site-packages/pandas/io/sql.py", line 728, in to_sql
    **engine_kwargs,
  File "/home/airflow/.local/lib/python3.7/site-packages/pandas/io/sql.py", line 1758, in to_sql
    dtype=dtype,
  File "/home/airflow/.local/lib/python3.7/site-packages/pandas/io/sql.py", line 1650, in prep_table
    table.create()
  File "/home/airflow/.local/lib/python3.7/site-packages/pandas/io/sql.py", line 860, in create
    self.pd_sql.drop_table(self.name, self.schema)
  File "/home/airflow/.local/lib/python3.7/site-packages/pandas/io/sql.py", line 1810, in drop_table
    self.get_table(table_name, schema).drop()
  File "/home/airflow/.local/lib/python3.7/site-packages/sqlalchemy/sql/schema.py", line 979, in drop
    bind._run_ddl_visitor(ddl.SchemaDropper, self, checkfirst=checkfirst)
  File "/home/airflow/.local/lib/python3.7/site-packages/sqlalchemy/engine/base.py", line 3238, in _run_ddl_visitor
    conn._run_ddl_visitor(visitorcallable, element, **kwargs)
  File "/home/airflow/.local/lib/python3.7/site-packages/sqlalchemy/engine/base.py", line 2221, in _run_ddl_visitor
    visitorcallable(self.dialect, self, **kwargs).traverse_single(element)
  File "/home/airflow/.local/lib/python3.7/site-packages/sqlalchemy/sql/visitors.py", line 524, in traverse_single
    return meth(obj, **kw)
  File "/home/airflow/.local/lib/python3.7/site-packages/sqlalchemy/sql/ddl.py", line 1106, in visit_table
    self.connection.execute(DropTable(table))
  File "/home/airflow/.local/lib/python3.7/site-packages/sqlalchemy/engine/base.py", line 1385, in execute
    return meth(self, multiparams, params, _EMPTY_EXECUTION_OPTS)
  File "/home/airflow/.local/lib/python3.7/site-packages/sqlalchemy/sql/ddl.py", line 81, in _execute_on_connection
    self, multiparams, params, execution_options
  File "/home/airflow/.local/lib/python3.7/site-packages/sqlalchemy/engine/base.py", line 1483, in _execute_ddl
    compiled,
  File "/home/airflow/.local/lib/python3.7/site-packages/sqlalchemy/engine/base.py", line 1954, in _execute_context
    e, statement, parameters, cursor, context
  File "/home/airflow/.local/lib/python3.7/site-packages/sqlalchemy/engine/base.py", line 2135, in _handle_dbapi_exception
    sqlalchemy_exception, with_traceback=exc_info[2], from_=e
  File "/home/airflow/.local/lib/python3.7/site-packages/sqlalchemy/util/compat.py", line 211, in raise_
    raise exception
  File "/home/airflow/.local/lib/python3.7/site-packages/sqlalchemy/engine/base.py", line 1911, in _execute_context
    cursor, statement, parameters, context
  File "/home/airflow/.local/lib/python3.7/site-packages/sqlalchemy/engine/default.py", line 736, in do_execute
    cursor.execute(statement, parameters)
sqlalchemy.exc.InternalError: (psycopg2.errors.DependentObjectsStillExist) cannot drop table idowilek6169_staging.orders because other objects depend on it
DETAIL:  view idowilek6169_staging.stg_orders depends on table idowilek6169_staging.orders
view idowilek6169_analytics.stg_orders depends on table idowilek6169_staging.orders
HINT:  Use DROP ... CASCADE to drop the dependent objects too.

[SQL: 
DROP TABLE idowilek6169_staging.orders]
(Background on this error at: https://sqlalche.me/e/14/2j85)
[2023-08-02T17:52:33.054+0000] {taskinstance.py:1350} INFO - Marking task as FAILED. dag_id=abc_data2bot_etl_dag, task_id=load_data_task, execution_date=20230802T174751, start_date=20230802T175219, end_date=20230802T175233
[2023-08-02T17:52:33.065+0000] {standard_task_runner.py:109} ERROR - Failed to execute job 14 for task load_data_task ((psycopg2.errors.DependentObjectsStillExist) cannot drop table idowilek6169_staging.orders because other objects depend on it
DETAIL:  view idowilek6169_staging.stg_orders depends on table idowilek6169_staging.orders
view idowilek6169_analytics.stg_orders depends on table idowilek6169_staging.orders
HINT:  Use DROP ... CASCADE to drop the dependent objects too.

[SQL: 
DROP TABLE idowilek6169_staging.orders]
(Background on this error at: https://sqlalche.me/e/14/2j85); 11085)
[2023-08-02T17:52:33.107+0000] {local_task_job_runner.py:225} INFO - Task exited with return code 1
