[2023-08-02T17:42:38.576+0000] {taskinstance.py:1103} INFO - Dependencies all met for dep_context=non-requeueable deps ti=<TaskInstance: abc_data2bot_etl_dag.extract_data_task manual__2023-08-02T17:42:36.304109+00:00 [queued]>
[2023-08-02T17:42:38.584+0000] {taskinstance.py:1103} INFO - Dependencies all met for dep_context=requeueable deps ti=<TaskInstance: abc_data2bot_etl_dag.extract_data_task manual__2023-08-02T17:42:36.304109+00:00 [queued]>
[2023-08-02T17:42:38.584+0000] {taskinstance.py:1308} INFO - Starting attempt 1 of 3
[2023-08-02T17:42:38.597+0000] {taskinstance.py:1327} INFO - Executing <Task(PythonOperator): extract_data_task> on 2023-08-02 17:42:36.304109+00:00
[2023-08-02T17:42:38.602+0000] {standard_task_runner.py:57} INFO - Started process 5607 to run task
[2023-08-02T17:42:38.604+0000] {standard_task_runner.py:84} INFO - Running: ['***', 'tasks', 'run', 'abc_data2bot_etl_dag', 'extract_data_task', 'manual__2023-08-02T17:42:36.304109+00:00', '--job-id', '7', '--raw', '--subdir', 'DAGS_FOLDER/etl_abc_dag.py', '--cfg-path', '/tmp/tmptylak4my']
[2023-08-02T17:42:38.605+0000] {standard_task_runner.py:85} INFO - Job 7: Subtask extract_data_task
[2023-08-02T17:42:38.645+0000] {task_command.py:410} INFO - Running <TaskInstance: abc_data2bot_etl_dag.extract_data_task manual__2023-08-02T17:42:36.304109+00:00 [running]> on host 22477bb0878f
[2023-08-02T17:42:38.720+0000] {taskinstance.py:1547} INFO - Exporting env vars: AIRFLOW_CTX_DAG_OWNER='idowu' AIRFLOW_CTX_DAG_ID='abc_data2bot_etl_dag' AIRFLOW_CTX_TASK_ID='extract_data_task' AIRFLOW_CTX_EXECUTION_DATE='2023-08-02T17:42:36.304109+00:00' AIRFLOW_CTX_TRY_NUMBER='1' AIRFLOW_CTX_DAG_RUN_ID='manual__2023-08-02T17:42:36.304109+00:00'
[2023-08-02T17:42:40.775+0000] {taskinstance.py:1824} ERROR - Task failed with exception
Traceback (most recent call last):
  File "/home/airflow/.local/lib/python3.7/site-packages/airflow/operators/python.py", line 181, in execute
    return_value = self.execute_callable()
  File "/home/airflow/.local/lib/python3.7/site-packages/airflow/operators/python.py", line 198, in execute_callable
    return self.python_callable(*self.op_args, **self.op_kwargs)
  File "/opt/airflow/dags/extract_data.py", line 38, in extract_save_data_all
    data_outputh_path = extract_data_save_locally(s3, bucket_name= bucket_name, data_to_download_name = data_name, data_local_folder_name=str(data_local_folder_name))
  File "/opt/airflow/dags/extract_data.py", line 30, in extract_data_save_locally
    s3.download_file(bucket_name, "orders_data/"+data_to_download_name,output_path)
  File "/home/airflow/.local/lib/python3.7/site-packages/boto3/s3/inject.py", line 195, in download_file
    callback=Callback,
  File "/home/airflow/.local/lib/python3.7/site-packages/boto3/s3/transfer.py", line 326, in download_file
    future.result()
  File "/home/airflow/.local/lib/python3.7/site-packages/s3transfer/futures.py", line 103, in result
    return self._coordinator.result()
  File "/home/airflow/.local/lib/python3.7/site-packages/s3transfer/futures.py", line 266, in result
    raise self._exception
  File "/home/airflow/.local/lib/python3.7/site-packages/s3transfer/tasks.py", line 269, in _main
    self._submit(transfer_future=transfer_future, **kwargs)
  File "/home/airflow/.local/lib/python3.7/site-packages/s3transfer/download.py", line 357, in _submit
    **transfer_future.meta.call_args.extra_args,
  File "/home/airflow/.local/lib/python3.7/site-packages/botocore/client.py", line 530, in _api_call
    return self._make_api_call(operation_name, kwargs)
  File "/home/airflow/.local/lib/python3.7/site-packages/botocore/client.py", line 964, in _make_api_call
    raise error_class(parsed_response, operation_name)
botocore.exceptions.ClientError: An error occurred (404) when calling the HeadObject operation: Not Found
[2023-08-02T17:42:40.783+0000] {taskinstance.py:1350} INFO - Marking task as UP_FOR_RETRY. dag_id=abc_data2bot_etl_dag, task_id=extract_data_task, execution_date=20230802T174236, start_date=20230802T174238, end_date=20230802T174240
[2023-08-02T17:42:40.793+0000] {standard_task_runner.py:109} ERROR - Failed to execute job 7 for task extract_data_task (An error occurred (404) when calling the HeadObject operation: Not Found; 5607)
[2023-08-02T17:42:40.825+0000] {local_task_job_runner.py:225} INFO - Task exited with return code 1
