[2023-08-03T07:51:10.606+0000] {taskinstance.py:1103} INFO - Dependencies all met for dep_context=non-requeueable deps ti=<TaskInstance: abc_data2bot_etl_dag.export_best_data manual__2023-08-03T07:50:20.191788+00:00 [queued]>
[2023-08-03T07:51:10.612+0000] {taskinstance.py:1103} INFO - Dependencies all met for dep_context=requeueable deps ti=<TaskInstance: abc_data2bot_etl_dag.export_best_data manual__2023-08-03T07:50:20.191788+00:00 [queued]>
[2023-08-03T07:51:10.612+0000] {taskinstance.py:1308} INFO - Starting attempt 1 of 3
[2023-08-03T07:51:10.625+0000] {taskinstance.py:1327} INFO - Executing <Task(PythonOperator): export_best_data> on 2023-08-03 07:50:20.191788+00:00
[2023-08-03T07:51:10.629+0000] {standard_task_runner.py:57} INFO - Started process 13409 to run task
[2023-08-03T07:51:10.632+0000] {standard_task_runner.py:84} INFO - Running: ['***', 'tasks', 'run', 'abc_data2bot_etl_dag', 'export_best_data', 'manual__2023-08-03T07:50:20.191788+00:00', '--job-id', '35', '--raw', '--subdir', 'DAGS_FOLDER/etl_abc_dag.py', '--cfg-path', '/tmp/tmpne49elaw']
[2023-08-03T07:51:10.633+0000] {standard_task_runner.py:85} INFO - Job 35: Subtask export_best_data
[2023-08-03T07:51:10.670+0000] {task_command.py:410} INFO - Running <TaskInstance: abc_data2bot_etl_dag.export_best_data manual__2023-08-03T07:50:20.191788+00:00 [running]> on host d75389520dc6
[2023-08-03T07:51:10.748+0000] {taskinstance.py:1547} INFO - Exporting env vars: AIRFLOW_CTX_DAG_OWNER='idowu' AIRFLOW_CTX_DAG_ID='abc_data2bot_etl_dag' AIRFLOW_CTX_TASK_ID='export_best_data' AIRFLOW_CTX_EXECUTION_DATE='2023-08-03T07:50:20.191788+00:00' AIRFLOW_CTX_TRY_NUMBER='1' AIRFLOW_CTX_DAG_RUN_ID='manual__2023-08-03T07:50:20.191788+00:00'
[2023-08-03T07:51:22.675+0000] {taskinstance.py:1824} ERROR - Task failed with exception
Traceback (most recent call last):
  File "/home/airflow/.local/lib/python3.7/site-packages/airflow/operators/python.py", line 181, in execute
    return_value = self.execute_callable()
  File "/home/airflow/.local/lib/python3.7/site-packages/airflow/operators/python.py", line 198, in execute_callable
    return self.python_callable(*self.op_args, **self.op_kwargs)
  File "/opt/airflow/dags/export_data.py", line 30, in export_best_performing_data
    s3.put_object(Bucket=bucket_name, Key=object_key, Body=csv_data, ACL='public-read')
NameError: name 'csv_data' is not defined
[2023-08-03T07:51:22.683+0000] {taskinstance.py:1350} INFO - Marking task as UP_FOR_RETRY. dag_id=abc_data2bot_etl_dag, task_id=export_best_data, execution_date=20230803T075020, start_date=20230803T075110, end_date=20230803T075122
[2023-08-03T07:51:22.699+0000] {standard_task_runner.py:109} ERROR - Failed to execute job 35 for task export_best_data (name 'csv_data' is not defined; 13409)
[2023-08-03T07:51:22.758+0000] {local_task_job_runner.py:225} INFO - Task exited with return code 1
[2023-08-03T07:51:22.796+0000] {taskinstance.py:2653} INFO - 0 downstream tasks scheduled from follow-on schedule check
