[2023-08-04T08:09:49.592+0000] {taskinstance.py:1103} INFO - Dependencies all met for dep_context=non-requeueable deps ti=<TaskInstance: abc_data2bot_etl_dag.load_data_task scheduled__2023-08-03T00:00:00+00:00 [queued]>
[2023-08-04T08:09:49.600+0000] {taskinstance.py:1103} INFO - Dependencies all met for dep_context=requeueable deps ti=<TaskInstance: abc_data2bot_etl_dag.load_data_task scheduled__2023-08-03T00:00:00+00:00 [queued]>
[2023-08-04T08:09:49.600+0000] {taskinstance.py:1308} INFO - Starting attempt 1 of 3
[2023-08-04T08:09:49.619+0000] {taskinstance.py:1327} INFO - Executing <Task(PythonOperator): load_data_task> on 2023-08-03 00:00:00+00:00
[2023-08-04T08:09:49.624+0000] {standard_task_runner.py:57} INFO - Started process 440 to run task
[2023-08-04T08:09:49.627+0000] {standard_task_runner.py:84} INFO - Running: ['***', 'tasks', 'run', 'abc_data2bot_etl_dag', 'load_data_task', 'scheduled__2023-08-03T00:00:00+00:00', '--job-id', '72', '--raw', '--subdir', 'DAGS_FOLDER/etl_abc_dag.py', '--cfg-path', '/tmp/tmp7qcw74ao']
[2023-08-04T08:09:49.628+0000] {standard_task_runner.py:85} INFO - Job 72: Subtask load_data_task
[2023-08-04T08:09:49.682+0000] {task_command.py:410} INFO - Running <TaskInstance: abc_data2bot_etl_dag.load_data_task scheduled__2023-08-03T00:00:00+00:00 [running]> on host d75389520dc6
[2023-08-04T08:09:49.768+0000] {taskinstance.py:1547} INFO - Exporting env vars: AIRFLOW_CTX_DAG_OWNER='idowu' AIRFLOW_CTX_DAG_ID='abc_data2bot_etl_dag' AIRFLOW_CTX_TASK_ID='load_data_task' AIRFLOW_CTX_EXECUTION_DATE='2023-08-03T00:00:00+00:00' AIRFLOW_CTX_TRY_NUMBER='1' AIRFLOW_CTX_DAG_RUN_ID='scheduled__2023-08-03T00:00:00+00:00'
[2023-08-04T08:10:03.805+0000] {python.py:183} INFO - Done. Returned value was: None
[2023-08-04T08:10:03.817+0000] {taskinstance.py:1350} INFO - Marking task as SUCCESS. dag_id=abc_data2bot_etl_dag, task_id=load_data_task, execution_date=20230803T000000, start_date=20230804T080949, end_date=20230804T081003
[2023-08-04T08:10:03.858+0000] {local_task_job_runner.py:225} INFO - Task exited with return code 0
[2023-08-04T15:33:14.023+0000] {taskinstance.py:1103} INFO - Dependencies all met for dep_context=non-requeueable deps ti=<TaskInstance: abc_data2bot_etl_dag.load_data_task scheduled__2023-08-03T00:00:00+00:00 [queued]>
[2023-08-04T15:33:14.042+0000] {taskinstance.py:1103} INFO - Dependencies all met for dep_context=requeueable deps ti=<TaskInstance: abc_data2bot_etl_dag.load_data_task scheduled__2023-08-03T00:00:00+00:00 [queued]>
[2023-08-04T15:33:14.042+0000] {taskinstance.py:1308} INFO - Starting attempt 1 of 3
[2023-08-04T15:33:14.066+0000] {taskinstance.py:1327} INFO - Executing <Task(PythonOperator): load_data_task> on 2023-08-03 00:00:00+00:00
[2023-08-04T15:33:14.074+0000] {standard_task_runner.py:57} INFO - Started process 796 to run task
[2023-08-04T15:33:14.077+0000] {standard_task_runner.py:84} INFO - Running: ['***', 'tasks', 'run', 'abc_data2bot_etl_dag', 'load_data_task', 'scheduled__2023-08-03T00:00:00+00:00', '--job-id', '6', '--raw', '--subdir', 'DAGS_FOLDER/etl_abc_dag.py', '--cfg-path', '/tmp/tmpuhvlaxvn']
[2023-08-04T15:33:14.078+0000] {standard_task_runner.py:85} INFO - Job 6: Subtask load_data_task
[2023-08-04T15:33:14.135+0000] {task_command.py:410} INFO - Running <TaskInstance: abc_data2bot_etl_dag.load_data_task scheduled__2023-08-03T00:00:00+00:00 [running]> on host 6eef4b6d916a
[2023-08-04T15:33:14.240+0000] {taskinstance.py:1547} INFO - Exporting env vars: AIRFLOW_CTX_DAG_OWNER='idowu' AIRFLOW_CTX_DAG_ID='abc_data2bot_etl_dag' AIRFLOW_CTX_TASK_ID='load_data_task' AIRFLOW_CTX_EXECUTION_DATE='2023-08-03T00:00:00+00:00' AIRFLOW_CTX_TRY_NUMBER='1' AIRFLOW_CTX_DAG_RUN_ID='scheduled__2023-08-03T00:00:00+00:00'
[2023-08-04T15:33:18.466+0000] {taskinstance.py:1824} ERROR - Task failed with exception
Traceback (most recent call last):
  File "/home/airflow/.local/lib/python3.7/site-packages/sqlalchemy/engine/base.py", line 1911, in _execute_context
    cursor, statement, parameters, context
  File "/home/airflow/.local/lib/python3.7/site-packages/sqlalchemy/engine/default.py", line 736, in do_execute
    cursor.execute(statement, parameters)
psycopg2.errors.UniqueViolation: duplicate key value violates unique constraint "pg_type_typname_nsp_index"
DETAIL:  Key (typname, typnamespace)=(orders, 30844) already exists.


The above exception was the direct cause of the following exception:

Traceback (most recent call last):
  File "/home/airflow/.local/lib/python3.7/site-packages/airflow/operators/python.py", line 181, in execute
    return_value = self.execute_callable()
  File "/home/airflow/.local/lib/python3.7/site-packages/airflow/operators/python.py", line 198, in execute_callable
    return self.python_callable(*self.op_args, **self.op_kwargs)
  File "/opt/airflow/dags/load_data.py", line 32, in load_data_warehouse
    data_df.to_sql(name=data_table_name, con=postgres_engine, if_exists = 'replace', schema= staging_schema_name,index = False)
  File "/home/airflow/.local/lib/python3.7/site-packages/pandas/core/generic.py", line 2882, in to_sql
    method=method,
  File "/home/airflow/.local/lib/python3.7/site-packages/pandas/io/sql.py", line 728, in to_sql
    **engine_kwargs,
  File "/home/airflow/.local/lib/python3.7/site-packages/pandas/io/sql.py", line 1758, in to_sql
    dtype=dtype,
  File "/home/airflow/.local/lib/python3.7/site-packages/pandas/io/sql.py", line 1650, in prep_table
    table.create()
  File "/home/airflow/.local/lib/python3.7/site-packages/pandas/io/sql.py", line 867, in create
    self._execute_create()
  File "/home/airflow/.local/lib/python3.7/site-packages/pandas/io/sql.py", line 853, in _execute_create
    self.table.create()
  File "/home/airflow/.local/lib/python3.7/site-packages/sqlalchemy/sql/schema.py", line 962, in create
    bind._run_ddl_visitor(ddl.SchemaGenerator, self, checkfirst=checkfirst)
  File "/home/airflow/.local/lib/python3.7/site-packages/sqlalchemy/engine/base.py", line 3238, in _run_ddl_visitor
    conn._run_ddl_visitor(visitorcallable, element, **kwargs)
  File "/home/airflow/.local/lib/python3.7/site-packages/sqlalchemy/engine/base.py", line 2221, in _run_ddl_visitor
    visitorcallable(self.dialect, self, **kwargs).traverse_single(element)
  File "/home/airflow/.local/lib/python3.7/site-packages/sqlalchemy/sql/visitors.py", line 524, in traverse_single
    return meth(obj, **kw)
  File "/home/airflow/.local/lib/python3.7/site-packages/sqlalchemy/sql/ddl.py", line 904, in visit_table
    include_foreign_key_constraints,  # noqa
  File "/home/airflow/.local/lib/python3.7/site-packages/sqlalchemy/engine/base.py", line 1385, in execute
    return meth(self, multiparams, params, _EMPTY_EXECUTION_OPTS)
  File "/home/airflow/.local/lib/python3.7/site-packages/sqlalchemy/sql/ddl.py", line 81, in _execute_on_connection
    self, multiparams, params, execution_options
  File "/home/airflow/.local/lib/python3.7/site-packages/sqlalchemy/engine/base.py", line 1483, in _execute_ddl
    compiled,
  File "/home/airflow/.local/lib/python3.7/site-packages/sqlalchemy/engine/base.py", line 1954, in _execute_context
    e, statement, parameters, cursor, context
  File "/home/airflow/.local/lib/python3.7/site-packages/sqlalchemy/engine/base.py", line 2135, in _handle_dbapi_exception
    sqlalchemy_exception, with_traceback=exc_info[2], from_=e
  File "/home/airflow/.local/lib/python3.7/site-packages/sqlalchemy/util/compat.py", line 211, in raise_
    raise exception
  File "/home/airflow/.local/lib/python3.7/site-packages/sqlalchemy/engine/base.py", line 1911, in _execute_context
    cursor, statement, parameters, context
  File "/home/airflow/.local/lib/python3.7/site-packages/sqlalchemy/engine/default.py", line 736, in do_execute
    cursor.execute(statement, parameters)
sqlalchemy.exc.IntegrityError: (psycopg2.errors.UniqueViolation) duplicate key value violates unique constraint "pg_type_typname_nsp_index"
DETAIL:  Key (typname, typnamespace)=(orders, 30844) already exists.

[SQL: 
CREATE TABLE idowilek6169_staging.orders (
	order_id BIGINT, 
	customer_id BIGINT, 
	order_date TIMESTAMP WITHOUT TIME ZONE, 
	product_id BIGINT, 
	unit_price BIGINT, 
	quantity BIGINT, 
	total_price BIGINT
)

]
(Background on this error at: https://sqlalche.me/e/14/gkpj)
[2023-08-04T15:33:18.487+0000] {taskinstance.py:1350} INFO - Marking task as UP_FOR_RETRY. dag_id=abc_data2bot_etl_dag, task_id=load_data_task, execution_date=20230803T000000, start_date=20230804T153314, end_date=20230804T153318
[2023-08-04T15:33:18.500+0000] {standard_task_runner.py:109} ERROR - Failed to execute job 6 for task load_data_task ((psycopg2.errors.UniqueViolation) duplicate key value violates unique constraint "pg_type_typname_nsp_index"
DETAIL:  Key (typname, typnamespace)=(orders, 30844) already exists.

[SQL: 
CREATE TABLE idowilek6169_staging.orders (
	order_id BIGINT, 
	customer_id BIGINT, 
	order_date TIMESTAMP WITHOUT TIME ZONE, 
	product_id BIGINT, 
	unit_price BIGINT, 
	quantity BIGINT, 
	total_price BIGINT
)

]
(Background on this error at: https://sqlalche.me/e/14/gkpj); 796)
[2023-08-04T15:33:18.541+0000] {local_task_job_runner.py:225} INFO - Task exited with return code 1
