[2023-08-02T17:26:12.344+0000] {taskinstance.py:1103} INFO - Dependencies all met for dep_context=non-requeueable deps ti=<TaskInstance: abc_data2bot_etl_dag.export_best_data manual__2023-08-02T17:22:02.850647+00:00 [queued]>
[2023-08-02T17:26:12.360+0000] {taskinstance.py:1103} INFO - Dependencies all met for dep_context=requeueable deps ti=<TaskInstance: abc_data2bot_etl_dag.export_best_data manual__2023-08-02T17:22:02.850647+00:00 [queued]>
[2023-08-02T17:26:12.360+0000] {taskinstance.py:1308} INFO - Starting attempt 3 of 3
[2023-08-02T17:26:12.380+0000] {taskinstance.py:1327} INFO - Executing <Task(PythonOperator): export_best_data> on 2023-08-02 17:22:02.850647+00:00
[2023-08-02T17:26:12.387+0000] {standard_task_runner.py:57} INFO - Started process 3330 to run task
[2023-08-02T17:26:12.391+0000] {standard_task_runner.py:84} INFO - Running: ['***', 'tasks', 'run', 'abc_data2bot_etl_dag', 'export_best_data', 'manual__2023-08-02T17:22:02.850647+00:00', '--job-id', '10', '--raw', '--subdir', 'DAGS_FOLDER/etl_abc_dag.py', '--cfg-path', '/tmp/tmp9gpfjvyb']
[2023-08-02T17:26:12.392+0000] {standard_task_runner.py:85} INFO - Job 10: Subtask export_best_data
[2023-08-02T17:26:12.462+0000] {task_command.py:410} INFO - Running <TaskInstance: abc_data2bot_etl_dag.export_best_data manual__2023-08-02T17:22:02.850647+00:00 [running]> on host eaa18f029fed
[2023-08-02T17:26:12.619+0000] {taskinstance.py:1547} INFO - Exporting env vars: AIRFLOW_CTX_DAG_OWNER='idowu' AIRFLOW_CTX_DAG_ID='abc_data2bot_etl_dag' AIRFLOW_CTX_TASK_ID='export_best_data' AIRFLOW_CTX_EXECUTION_DATE='2023-08-02T17:22:02.850647+00:00' AIRFLOW_CTX_TRY_NUMBER='3' AIRFLOW_CTX_DAG_RUN_ID='manual__2023-08-02T17:22:02.850647+00:00'
[2023-08-02T17:26:12.623+0000] {taskinstance.py:1824} ERROR - Task failed with exception
Traceback (most recent call last):
  File "/home/airflow/.local/lib/python3.7/site-packages/airflow/operators/python.py", line 181, in execute
    return_value = self.execute_callable()
  File "/home/airflow/.local/lib/python3.7/site-packages/airflow/operators/python.py", line 198, in execute_callable
    return self.python_callable(*self.op_args, **self.op_kwargs)
TypeError: export_best_performing_data() missing 1 required positional argument: 'username'
[2023-08-02T17:26:12.635+0000] {taskinstance.py:1350} INFO - Marking task as FAILED. dag_id=abc_data2bot_etl_dag, task_id=export_best_data, execution_date=20230802T172202, start_date=20230802T172612, end_date=20230802T172612
[2023-08-02T17:26:12.660+0000] {standard_task_runner.py:109} ERROR - Failed to execute job 10 for task export_best_data (export_best_performing_data() missing 1 required positional argument: 'username'; 3330)
[2023-08-02T17:26:12.683+0000] {local_task_job_runner.py:225} INFO - Task exited with return code 1
[2023-08-02T17:26:12.706+0000] {taskinstance.py:2653} INFO - 0 downstream tasks scheduled from follow-on schedule check
