[2023-08-02T17:58:54.707+0000] {taskinstance.py:1103} INFO - Dependencies all met for dep_context=non-requeueable deps ti=<TaskInstance: abc_data2bot_etl_dag.extract_data_task manual__2023-08-02T17:58:52.911650+00:00 [queued]>
[2023-08-02T17:58:54.716+0000] {taskinstance.py:1103} INFO - Dependencies all met for dep_context=requeueable deps ti=<TaskInstance: abc_data2bot_etl_dag.extract_data_task manual__2023-08-02T17:58:52.911650+00:00 [queued]>
[2023-08-02T17:58:54.716+0000] {taskinstance.py:1308} INFO - Starting attempt 1 of 3
[2023-08-02T17:58:54.729+0000] {taskinstance.py:1327} INFO - Executing <Task(PythonOperator): extract_data_task> on 2023-08-02 17:58:52.911650+00:00
[2023-08-02T17:58:54.736+0000] {standard_task_runner.py:57} INFO - Started process 14748 to run task
[2023-08-02T17:58:54.738+0000] {standard_task_runner.py:84} INFO - Running: ['***', 'tasks', 'run', 'abc_data2bot_etl_dag', 'extract_data_task', 'manual__2023-08-02T17:58:52.911650+00:00', '--job-id', '16', '--raw', '--subdir', 'DAGS_FOLDER/etl_abc_dag.py', '--cfg-path', '/tmp/tmpxjk_261t']
[2023-08-02T17:58:54.739+0000] {standard_task_runner.py:85} INFO - Job 16: Subtask extract_data_task
[2023-08-02T17:58:54.783+0000] {task_command.py:410} INFO - Running <TaskInstance: abc_data2bot_etl_dag.extract_data_task manual__2023-08-02T17:58:52.911650+00:00 [running]> on host 22477bb0878f
[2023-08-02T17:58:54.874+0000] {taskinstance.py:1547} INFO - Exporting env vars: AIRFLOW_CTX_DAG_OWNER='idowu' AIRFLOW_CTX_DAG_ID='abc_data2bot_etl_dag' AIRFLOW_CTX_TASK_ID='extract_data_task' AIRFLOW_CTX_EXECUTION_DATE='2023-08-02T17:58:52.911650+00:00' AIRFLOW_CTX_TRY_NUMBER='1' AIRFLOW_CTX_DAG_RUN_ID='manual__2023-08-02T17:58:52.911650+00:00'
[2023-08-02T17:59:40.199+0000] {local_task_job_runner.py:292} WARNING - State of this instance has been externally set to restarting. Terminating instance.
[2023-08-02T17:59:40.205+0000] {process_utils.py:135} INFO - Sending Signals.SIGTERM to group 14748. PIDs of all processes in the group: [14748]
[2023-08-02T17:59:40.205+0000] {process_utils.py:86} INFO - Sending the signal Signals.SIGTERM to group 14748
[2023-08-02T17:59:40.205+0000] {taskinstance.py:1517} ERROR - Received SIGTERM. Terminating subprocesses.
[2023-08-02T17:59:51.013+0000] {taskinstance.py:1824} ERROR - Task failed with exception
Traceback (most recent call last):
  File "/home/airflow/.local/lib/python3.7/site-packages/airflow/operators/python.py", line 181, in execute
    return_value = self.execute_callable()
  File "/home/airflow/.local/lib/python3.7/site-packages/airflow/operators/python.py", line 198, in execute_callable
    return self.python_callable(*self.op_args, **self.op_kwargs)
  File "/opt/airflow/dags/extract_data.py", line 38, in extract_save_data_all
    data_outputh_path = extract_data_save_locally(s3, bucket_name= bucket_name, data_to_download_name = data_name, data_local_folder_name=str(data_local_folder_name))
  File "/opt/airflow/dags/extract_data.py", line 30, in extract_data_save_locally
    s3.download_file(bucket_name, "orders_data/"+data_to_download_name+'.csv',output_path)
  File "/home/airflow/.local/lib/python3.7/site-packages/boto3/s3/inject.py", line 195, in download_file
    callback=Callback,
  File "/home/airflow/.local/lib/python3.7/site-packages/boto3/s3/transfer.py", line 326, in download_file
    future.result()
  File "/home/airflow/.local/lib/python3.7/site-packages/s3transfer/futures.py", line 103, in result
    return self._coordinator.result()
  File "/home/airflow/.local/lib/python3.7/site-packages/s3transfer/futures.py", line 261, in result
    self._done_event.wait(MAXINT)
  File "/usr/local/lib/python3.7/threading.py", line 552, in wait
    signaled = self._cond.wait(timeout)
  File "/usr/local/lib/python3.7/threading.py", line 296, in wait
    waiter.acquire()
  File "/home/airflow/.local/lib/python3.7/site-packages/airflow/models/taskinstance.py", line 1519, in signal_handler
    raise AirflowException("Task received SIGTERM signal")
airflow.exceptions.AirflowException: Task received SIGTERM signal
[2023-08-02T17:59:51.018+0000] {taskinstance.py:1350} INFO - Marking task as UP_FOR_RETRY. dag_id=abc_data2bot_etl_dag, task_id=extract_data_task, execution_date=20230802T175852, start_date=20230802T175854, end_date=20230802T175951
[2023-08-02T17:59:51.031+0000] {standard_task_runner.py:109} ERROR - Failed to execute job 16 for task extract_data_task (Task received SIGTERM signal; 14748)
[2023-08-02T17:59:51.061+0000] {process_utils.py:79} INFO - Process psutil.Process(pid=14748, status='terminated', exitcode=1, started='17:58:54') (14748) terminated with exit code 1
