[2023-08-03T08:01:03.232+0000] {taskinstance.py:1103} INFO - Dependencies all met for dep_context=non-requeueable deps ti=<TaskInstance: abc_data2bot_etl_dag.export_best_data manual__2023-08-03T07:53:12.109521+00:00 [queued]>
[2023-08-03T08:01:03.239+0000] {taskinstance.py:1103} INFO - Dependencies all met for dep_context=requeueable deps ti=<TaskInstance: abc_data2bot_etl_dag.export_best_data manual__2023-08-03T07:53:12.109521+00:00 [queued]>
[2023-08-03T08:01:03.239+0000] {taskinstance.py:1308} INFO - Starting attempt 3 of 3
[2023-08-03T08:01:03.253+0000] {taskinstance.py:1327} INFO - Executing <Task(PythonOperator): export_best_data> on 2023-08-03 07:53:12.109521+00:00
[2023-08-03T08:01:03.257+0000] {standard_task_runner.py:57} INFO - Started process 19007 to run task
[2023-08-03T08:01:03.259+0000] {standard_task_runner.py:84} INFO - Running: ['***', 'tasks', 'run', 'abc_data2bot_etl_dag', 'export_best_data', 'manual__2023-08-03T07:53:12.109521+00:00', '--job-id', '48', '--raw', '--subdir', 'DAGS_FOLDER/etl_abc_dag.py', '--cfg-path', '/tmp/tmphlph__b0']
[2023-08-03T08:01:03.260+0000] {standard_task_runner.py:85} INFO - Job 48: Subtask export_best_data
[2023-08-03T08:01:03.296+0000] {task_command.py:410} INFO - Running <TaskInstance: abc_data2bot_etl_dag.export_best_data manual__2023-08-03T07:53:12.109521+00:00 [running]> on host d75389520dc6
[2023-08-03T08:01:03.364+0000] {taskinstance.py:1547} INFO - Exporting env vars: AIRFLOW_CTX_DAG_OWNER='idowu' AIRFLOW_CTX_DAG_ID='abc_data2bot_etl_dag' AIRFLOW_CTX_TASK_ID='export_best_data' AIRFLOW_CTX_EXECUTION_DATE='2023-08-03T07:53:12.109521+00:00' AIRFLOW_CTX_TRY_NUMBER='3' AIRFLOW_CTX_DAG_RUN_ID='manual__2023-08-03T07:53:12.109521+00:00'
[2023-08-03T08:01:13.570+0000] {taskinstance.py:1824} ERROR - Task failed with exception
Traceback (most recent call last):
  File "/home/airflow/.local/lib/python3.7/site-packages/airflow/operators/python.py", line 181, in execute
    return_value = self.execute_callable()
  File "/home/airflow/.local/lib/python3.7/site-packages/airflow/operators/python.py", line 198, in execute_callable
    return self.python_callable(*self.op_args, **self.op_kwargs)
  File "/opt/airflow/dags/export_data.py", line 30, in export_best_performing_data
    s3.put_object(Bucket=bucket_name, Key=object_key, Body=best_performing_csv_data, ACL='public-read')
  File "/home/airflow/.local/lib/python3.7/site-packages/botocore/client.py", line 386, in _api_call
    return self._make_api_call(operation_name, kwargs)
  File "/home/airflow/.local/lib/python3.7/site-packages/botocore/client.py", line 678, in _make_api_call
    api_params, operation_model, context=request_context)
  File "/home/airflow/.local/lib/python3.7/site-packages/botocore/client.py", line 726, in _convert_to_request_dict
    api_params, operation_model)
  File "/home/airflow/.local/lib/python3.7/site-packages/botocore/validate.py", line 319, in serialize_to_request
    raise ParamValidationError(report=report.generate_report())
botocore.exceptions.ParamValidationError: Parameter validation failed:
Invalid type for parameter Body, value: None, type: <class 'NoneType'>, valid types: <class 'bytes'>, <class 'bytearray'>, file-like object
[2023-08-03T08:01:13.578+0000] {taskinstance.py:1350} INFO - Marking task as FAILED. dag_id=abc_data2bot_etl_dag, task_id=export_best_data, execution_date=20230803T075312, start_date=20230803T080103, end_date=20230803T080113
[2023-08-03T08:01:13.591+0000] {standard_task_runner.py:109} ERROR - Failed to execute job 48 for task export_best_data (Parameter validation failed:
Invalid type for parameter Body, value: None, type: <class 'NoneType'>, valid types: <class 'bytes'>, <class 'bytearray'>, file-like object; 19007)
[2023-08-03T08:01:13.624+0000] {local_task_job_runner.py:225} INFO - Task exited with return code 1
[2023-08-03T08:01:13.637+0000] {taskinstance.py:2653} INFO - 0 downstream tasks scheduled from follow-on schedule check
