[2023-08-02T17:22:07.652+0000] {taskinstance.py:1103} INFO - Dependencies all met for dep_context=non-requeueable deps ti=<TaskInstance: abc_data2bot_etl_dag.extract_data_task manual__2023-08-02T17:22:02.850647+00:00 [queued]>
[2023-08-02T17:22:07.677+0000] {taskinstance.py:1103} INFO - Dependencies all met for dep_context=requeueable deps ti=<TaskInstance: abc_data2bot_etl_dag.extract_data_task manual__2023-08-02T17:22:02.850647+00:00 [queued]>
[2023-08-02T17:22:07.678+0000] {taskinstance.py:1308} INFO - Starting attempt 1 of 3
[2023-08-02T17:22:07.711+0000] {taskinstance.py:1327} INFO - Executing <Task(PythonOperator): extract_data_task> on 2023-08-02 17:22:02.850647+00:00
[2023-08-02T17:22:07.721+0000] {standard_task_runner.py:57} INFO - Started process 1016 to run task
[2023-08-02T17:22:07.726+0000] {standard_task_runner.py:84} INFO - Running: ['***', 'tasks', 'run', 'abc_data2bot_etl_dag', 'extract_data_task', 'manual__2023-08-02T17:22:02.850647+00:00', '--job-id', '3', '--raw', '--subdir', 'DAGS_FOLDER/etl_abc_dag.py', '--cfg-path', '/tmp/tmpawcg4ov7']
[2023-08-02T17:22:07.727+0000] {standard_task_runner.py:85} INFO - Job 3: Subtask extract_data_task
[2023-08-02T17:22:07.878+0000] {task_command.py:410} INFO - Running <TaskInstance: abc_data2bot_etl_dag.extract_data_task manual__2023-08-02T17:22:02.850647+00:00 [running]> on host eaa18f029fed
[2023-08-02T17:22:08.346+0000] {taskinstance.py:1547} INFO - Exporting env vars: AIRFLOW_CTX_DAG_OWNER='idowu' AIRFLOW_CTX_DAG_ID='abc_data2bot_etl_dag' AIRFLOW_CTX_TASK_ID='extract_data_task' AIRFLOW_CTX_EXECUTION_DATE='2023-08-02T17:22:02.850647+00:00' AIRFLOW_CTX_TRY_NUMBER='1' AIRFLOW_CTX_DAG_RUN_ID='manual__2023-08-02T17:22:02.850647+00:00'
[2023-08-02T17:22:08.352+0000] {taskinstance.py:1824} ERROR - Task failed with exception
Traceback (most recent call last):
  File "/home/airflow/.local/lib/python3.7/site-packages/airflow/operators/python.py", line 181, in execute
    return_value = self.execute_callable()
  File "/home/airflow/.local/lib/python3.7/site-packages/airflow/operators/python.py", line 198, in execute_callable
    return self.python_callable(*self.op_args, **self.op_kwargs)
  File "/opt/airflow/dags/extract_data.py", line 38, in extract_save_data_all
    data_outputh_path = extract_data_save_locally(s3_client=boto3.client, bucket_name= bucket_name, data_to_download_name = data_name, data_local_folder_name=str(data_local_folder_name))
  File "/opt/airflow/dags/extract_data.py", line 27, in extract_data_save_locally
    s3 = s3_client.client('s3', config=Config(signature_version= UNSIGNED))
AttributeError: 'function' object has no attribute 'client'
[2023-08-02T17:22:08.460+0000] {taskinstance.py:1350} INFO - Marking task as UP_FOR_RETRY. dag_id=abc_data2bot_etl_dag, task_id=extract_data_task, execution_date=20230802T172202, start_date=20230802T172207, end_date=20230802T172208
[2023-08-02T17:22:08.637+0000] {standard_task_runner.py:109} ERROR - Failed to execute job 3 for task extract_data_task ('function' object has no attribute 'client'; 1016)
[2023-08-02T17:22:08.728+0000] {local_task_job_runner.py:225} INFO - Task exited with return code 1
[2023-08-02T17:22:08.798+0000] {taskinstance.py:2653} INFO - 0 downstream tasks scheduled from follow-on schedule check
