[2023-08-03T07:45:42.149+0000] {taskinstance.py:1103} INFO - Dependencies all met for dep_context=non-requeueable deps ti=<TaskInstance: abc_data2bot_etl_dag.export_best_data manual__2023-08-03T07:44:27.873377+00:00 [queued]>
[2023-08-03T07:45:42.157+0000] {taskinstance.py:1103} INFO - Dependencies all met for dep_context=requeueable deps ti=<TaskInstance: abc_data2bot_etl_dag.export_best_data manual__2023-08-03T07:44:27.873377+00:00 [queued]>
[2023-08-03T07:45:42.157+0000] {taskinstance.py:1308} INFO - Starting attempt 1 of 3
[2023-08-03T07:45:42.170+0000] {taskinstance.py:1327} INFO - Executing <Task(PythonOperator): export_best_data> on 2023-08-03 07:44:27.873377+00:00
[2023-08-03T07:45:42.175+0000] {standard_task_runner.py:57} INFO - Started process 10165 to run task
[2023-08-03T07:45:42.178+0000] {standard_task_runner.py:84} INFO - Running: ['***', 'tasks', 'run', 'abc_data2bot_etl_dag', 'export_best_data', 'manual__2023-08-03T07:44:27.873377+00:00', '--job-id', '25', '--raw', '--subdir', 'DAGS_FOLDER/etl_abc_dag.py', '--cfg-path', '/tmp/tmpfntqwxx5']
[2023-08-03T07:45:42.179+0000] {standard_task_runner.py:85} INFO - Job 25: Subtask export_best_data
[2023-08-03T07:45:42.218+0000] {task_command.py:410} INFO - Running <TaskInstance: abc_data2bot_etl_dag.export_best_data manual__2023-08-03T07:44:27.873377+00:00 [running]> on host d75389520dc6
[2023-08-03T07:45:42.300+0000] {taskinstance.py:1547} INFO - Exporting env vars: AIRFLOW_CTX_DAG_OWNER='idowu' AIRFLOW_CTX_DAG_ID='abc_data2bot_etl_dag' AIRFLOW_CTX_TASK_ID='export_best_data' AIRFLOW_CTX_EXECUTION_DATE='2023-08-03T07:44:27.873377+00:00' AIRFLOW_CTX_TRY_NUMBER='1' AIRFLOW_CTX_DAG_RUN_ID='manual__2023-08-03T07:44:27.873377+00:00'
[2023-08-03T07:45:54.808+0000] {taskinstance.py:1824} ERROR - Task failed with exception
Traceback (most recent call last):
  File "/home/airflow/.local/lib/python3.7/site-packages/airflow/operators/python.py", line 181, in execute
    return_value = self.execute_callable()
  File "/home/airflow/.local/lib/python3.7/site-packages/airflow/operators/python.py", line 198, in execute_callable
    return self.python_callable(*self.op_args, **self.op_kwargs)
  File "/opt/airflow/dags/export_data.py", line 28, in export_best_performing_data
    s3.put_object(Bucket=bucket_name, Key=object_key, Body=csv_data, ACL='public-read')
NameError: name 'bucket_name' is not defined
[2023-08-03T07:45:54.816+0000] {taskinstance.py:1350} INFO - Marking task as UP_FOR_RETRY. dag_id=abc_data2bot_etl_dag, task_id=export_best_data, execution_date=20230803T074427, start_date=20230803T074542, end_date=20230803T074554
[2023-08-03T07:45:54.832+0000] {standard_task_runner.py:109} ERROR - Failed to execute job 25 for task export_best_data (name 'bucket_name' is not defined; 10165)
[2023-08-03T07:45:54.865+0000] {local_task_job_runner.py:225} INFO - Task exited with return code 1
[2023-08-03T07:45:54.879+0000] {taskinstance.py:2653} INFO - 0 downstream tasks scheduled from follow-on schedule check
