[2023-08-03T07:47:56.389+0000] {taskinstance.py:1103} INFO - Dependencies all met for dep_context=non-requeueable deps ti=<TaskInstance: abc_data2bot_etl_dag.export_best_data manual__2023-08-03T07:44:27.873377+00:00 [queued]>
[2023-08-03T07:47:56.396+0000] {taskinstance.py:1103} INFO - Dependencies all met for dep_context=requeueable deps ti=<TaskInstance: abc_data2bot_etl_dag.export_best_data manual__2023-08-03T07:44:27.873377+00:00 [queued]>
[2023-08-03T07:47:56.396+0000] {taskinstance.py:1308} INFO - Starting attempt 2 of 3
[2023-08-03T07:47:56.411+0000] {taskinstance.py:1327} INFO - Executing <Task(PythonOperator): export_best_data> on 2023-08-03 07:44:27.873377+00:00
[2023-08-03T07:47:56.416+0000] {standard_task_runner.py:57} INFO - Started process 11361 to run task
[2023-08-03T07:47:56.419+0000] {standard_task_runner.py:84} INFO - Running: ['***', 'tasks', 'run', 'abc_data2bot_etl_dag', 'export_best_data', 'manual__2023-08-03T07:44:27.873377+00:00', '--job-id', '28', '--raw', '--subdir', 'DAGS_FOLDER/etl_abc_dag.py', '--cfg-path', '/tmp/tmpshb3x87s']
[2023-08-03T07:47:56.419+0000] {standard_task_runner.py:85} INFO - Job 28: Subtask export_best_data
[2023-08-03T07:47:56.459+0000] {task_command.py:410} INFO - Running <TaskInstance: abc_data2bot_etl_dag.export_best_data manual__2023-08-03T07:44:27.873377+00:00 [running]> on host d75389520dc6
[2023-08-03T07:47:56.534+0000] {taskinstance.py:1547} INFO - Exporting env vars: AIRFLOW_CTX_DAG_OWNER='idowu' AIRFLOW_CTX_DAG_ID='abc_data2bot_etl_dag' AIRFLOW_CTX_TASK_ID='export_best_data' AIRFLOW_CTX_EXECUTION_DATE='2023-08-03T07:44:27.873377+00:00' AIRFLOW_CTX_TRY_NUMBER='2' AIRFLOW_CTX_DAG_RUN_ID='manual__2023-08-03T07:44:27.873377+00:00'
[2023-08-03T07:48:06.323+0000] {taskinstance.py:1824} ERROR - Task failed with exception
Traceback (most recent call last):
  File "/home/airflow/.local/lib/python3.7/site-packages/airflow/operators/python.py", line 181, in execute
    return_value = self.execute_callable()
  File "/home/airflow/.local/lib/python3.7/site-packages/airflow/operators/python.py", line 198, in execute_callable
    return self.python_callable(*self.op_args, **self.op_kwargs)
  File "/opt/airflow/dags/export_data.py", line 30, in export_best_performing_data
    s3.put_object(Bucket=bucket_name, Key=object_key, Body=csv_data, ACL='public-read')
NameError: name 'bucket_name' is not defined
[2023-08-03T07:48:06.330+0000] {taskinstance.py:1350} INFO - Marking task as UP_FOR_RETRY. dag_id=abc_data2bot_etl_dag, task_id=export_best_data, execution_date=20230803T074427, start_date=20230803T074756, end_date=20230803T074806
[2023-08-03T07:48:06.342+0000] {standard_task_runner.py:109} ERROR - Failed to execute job 28 for task export_best_data (name 'bucket_name' is not defined; 11361)
[2023-08-03T07:48:06.383+0000] {local_task_job_runner.py:225} INFO - Task exited with return code 1
[2023-08-03T07:48:06.399+0000] {taskinstance.py:2653} INFO - 0 downstream tasks scheduled from follow-on schedule check
