[2023-08-02T17:22:07.675+0000] {taskinstance.py:1103} INFO - Dependencies all met for dep_context=non-requeueable deps ti=<TaskInstance: abc_data2bot_etl_dag.load_data_task manual__2023-08-02T17:22:02.850647+00:00 [queued]>
[2023-08-02T17:22:07.691+0000] {taskinstance.py:1103} INFO - Dependencies all met for dep_context=requeueable deps ti=<TaskInstance: abc_data2bot_etl_dag.load_data_task manual__2023-08-02T17:22:02.850647+00:00 [queued]>
[2023-08-02T17:22:07.692+0000] {taskinstance.py:1308} INFO - Starting attempt 1 of 3
[2023-08-02T17:22:07.736+0000] {taskinstance.py:1327} INFO - Executing <Task(PythonOperator): load_data_task> on 2023-08-02 17:22:02.850647+00:00
[2023-08-02T17:22:07.742+0000] {standard_task_runner.py:57} INFO - Started process 1020 to run task
[2023-08-02T17:22:07.745+0000] {standard_task_runner.py:84} INFO - Running: ['***', 'tasks', 'run', 'abc_data2bot_etl_dag', 'load_data_task', 'manual__2023-08-02T17:22:02.850647+00:00', '--job-id', '6', '--raw', '--subdir', 'DAGS_FOLDER/etl_abc_dag.py', '--cfg-path', '/tmp/tmp2a3_pa3d']
[2023-08-02T17:22:07.746+0000] {standard_task_runner.py:85} INFO - Job 6: Subtask load_data_task
[2023-08-02T17:22:07.883+0000] {task_command.py:410} INFO - Running <TaskInstance: abc_data2bot_etl_dag.load_data_task manual__2023-08-02T17:22:02.850647+00:00 [running]> on host eaa18f029fed
[2023-08-02T17:22:08.345+0000] {taskinstance.py:1547} INFO - Exporting env vars: AIRFLOW_CTX_DAG_OWNER='idowu' AIRFLOW_CTX_DAG_ID='abc_data2bot_etl_dag' AIRFLOW_CTX_TASK_ID='load_data_task' AIRFLOW_CTX_EXECUTION_DATE='2023-08-02T17:22:02.850647+00:00' AIRFLOW_CTX_TRY_NUMBER='1' AIRFLOW_CTX_DAG_RUN_ID='manual__2023-08-02T17:22:02.850647+00:00'
[2023-08-02T17:22:08.364+0000] {taskinstance.py:1824} ERROR - Task failed with exception
Traceback (most recent call last):
  File "/home/airflow/.local/lib/python3.7/site-packages/airflow/operators/python.py", line 181, in execute
    return_value = self.execute_callable()
  File "/home/airflow/.local/lib/python3.7/site-packages/airflow/operators/python.py", line 198, in execute_callable
    return self.python_callable(*self.op_args, **self.op_kwargs)
  File "/opt/airflow/dags/load_data.py", line 12, in load_data_warehouse
    for keys,values in data_to_download_dict.items():
AttributeError: 'NoneType' object has no attribute 'items'
[2023-08-02T17:22:08.460+0000] {taskinstance.py:1350} INFO - Marking task as UP_FOR_RETRY. dag_id=abc_data2bot_etl_dag, task_id=load_data_task, execution_date=20230802T172202, start_date=20230802T172207, end_date=20230802T172208
[2023-08-02T17:22:08.609+0000] {standard_task_runner.py:109} ERROR - Failed to execute job 6 for task load_data_task ('NoneType' object has no attribute 'items'; 1020)
[2023-08-02T17:22:08.714+0000] {local_task_job_runner.py:225} INFO - Task exited with return code 1
[2023-08-02T17:22:08.735+0000] {taskinstance.py:2653} INFO - 0 downstream tasks scheduled from follow-on schedule check
