[2023-08-02T18:01:13.231+0000] {taskinstance.py:1103} INFO - Dependencies all met for dep_context=non-requeueable deps ti=<TaskInstance: abc_data2bot_etl_dag.export_best_data manual__2023-08-02T17:57:41.543111+00:00 [queued]>
[2023-08-02T18:01:13.238+0000] {taskinstance.py:1103} INFO - Dependencies all met for dep_context=requeueable deps ti=<TaskInstance: abc_data2bot_etl_dag.export_best_data manual__2023-08-02T17:57:41.543111+00:00 [queued]>
[2023-08-02T18:01:13.238+0000] {taskinstance.py:1308} INFO - Starting attempt 1 of 3
[2023-08-02T18:01:13.252+0000] {taskinstance.py:1327} INFO - Executing <Task(PythonOperator): export_best_data> on 2023-08-02 17:57:41.543111+00:00
[2023-08-02T18:01:13.257+0000] {standard_task_runner.py:57} INFO - Started process 16140 to run task
[2023-08-02T18:01:13.260+0000] {standard_task_runner.py:84} INFO - Running: ['***', 'tasks', 'run', 'abc_data2bot_etl_dag', 'export_best_data', 'manual__2023-08-02T17:57:41.543111+00:00', '--job-id', '19', '--raw', '--subdir', 'DAGS_FOLDER/etl_abc_dag.py', '--cfg-path', '/tmp/tmp2u5r9aw7']
[2023-08-02T18:01:13.261+0000] {standard_task_runner.py:85} INFO - Job 19: Subtask export_best_data
[2023-08-02T18:01:13.301+0000] {task_command.py:410} INFO - Running <TaskInstance: abc_data2bot_etl_dag.export_best_data manual__2023-08-02T17:57:41.543111+00:00 [running]> on host 22477bb0878f
[2023-08-02T18:01:13.372+0000] {taskinstance.py:1547} INFO - Exporting env vars: AIRFLOW_CTX_DAG_OWNER='idowu' AIRFLOW_CTX_DAG_ID='abc_data2bot_etl_dag' AIRFLOW_CTX_TASK_ID='export_best_data' AIRFLOW_CTX_EXECUTION_DATE='2023-08-02T17:57:41.543111+00:00' AIRFLOW_CTX_TRY_NUMBER='1' AIRFLOW_CTX_DAG_RUN_ID='manual__2023-08-02T17:57:41.543111+00:00'
[2023-08-02T18:01:13.373+0000] {taskinstance.py:1824} ERROR - Task failed with exception
Traceback (most recent call last):
  File "/home/airflow/.local/lib/python3.7/site-packages/airflow/operators/python.py", line 181, in execute
    return_value = self.execute_callable()
  File "/home/airflow/.local/lib/python3.7/site-packages/airflow/operators/python.py", line 198, in execute_callable
    return self.python_callable(*self.op_args, **self.op_kwargs)
TypeError: export_best_performing_data() missing 1 required positional argument: 'username'
[2023-08-02T18:01:13.380+0000] {taskinstance.py:1350} INFO - Marking task as UP_FOR_RETRY. dag_id=abc_data2bot_etl_dag, task_id=export_best_data, execution_date=20230802T175741, start_date=20230802T180113, end_date=20230802T180113
[2023-08-02T18:01:13.391+0000] {standard_task_runner.py:109} ERROR - Failed to execute job 19 for task export_best_data (export_best_performing_data() missing 1 required positional argument: 'username'; 16140)
[2023-08-02T18:01:13.431+0000] {local_task_job_runner.py:225} INFO - Task exited with return code 1
[2023-08-02T18:01:13.446+0000] {taskinstance.py:2653} INFO - 0 downstream tasks scheduled from follow-on schedule check
